<mujoco model="stair-hard">
  <asset>
    <!-- <texture name="skybox" type="skybox" builtin="flat" rgb1="1 1 1" width="800" height="800" />
    <texture name="grid" type="2d" builtin="flat" rgb1="0.8 0.8 0.8" width="300" height="300" mark="edge"/>
    <material name="grid" texture="grid"/>
    <material name="self" rgba=".7 .5 .3 1"/> -->
    <texture name="skybox" type="skybox" builtin="gradient" rgb1=".2 .3 .4" rgb2="0 0 0" width="800" height="800" mark="random" markrgb="1 1 1"/>
    <texture name="grid" type="2d" builtin="checker" rgb1=".3 .2 .1" rgb2=".4 .3 .2" width="300" height="300" mark="edge" markrgb=".4 .3 .2"/>
    <material name="grid" texture="grid" texrepeat="1 1" texuniform="true" reflectance=".2"/>
    <material name="self" rgba=".7 .5 .3 1"/>
  </asset>
  <visual>
    <headlight ambient=".4 .4 .4" diffuse=".8 .8 .8" specular="0.1 0.1 0.1"/>
    <map znear=".001"/>
    <quality shadowsize="16384"/>
  </visual>
  <compiler angle="degree" coordinate="global" inertiafromgeom="true"/>
  <default>
    <joint armature="1" damping="1" limited="true"/>
    <geom conaffinity="0" condim="3" density="5.0" margin="0.01" friction="1 0.5 0.5" rgba=".7 .5 .3 1"/>
  </default>
  <option integrator="RK4" timestep="0.002"/>
  <worldbody>
    <light cutoff="100" diffuse="1 1 1" dir="0.3 0 -1.3" directional="true" exponent="1" pos="-30 0 130" specular=".1 .1 .1"/>
    <geom conaffinity="1" condim="3" name="floor" pos="0 0 0" rgba="1 1 1 1" size="30 30 .125" type="plane" material="grid" group="1"/>
    <geom name='stair1' material="grid" pos='51.5 0 -0.005' type='hfield' conaffinity='1' rgba="1 1 1 1" condim='3' hfield="stair" group="1"/>
    <geom name='stair2' material="grid" pos='151.3 0 40' type='hfield' conaffinity='1' rgba="1 1 1 1" condim='3' hfield="stair" group="1"/>
    <geom name='stair3' material="grid" pos='251.1 0 80.005' type='hfield' conaffinity='1' rgba="1 1 1 1" condim='3' hfield="stair" group="1"/>
    <geom name='stair4' material="grid" pos='350.9 0 120.01' type='hfield' conaffinity='1' rgba="1 1 1 1" condim='3' hfield="stair" group="1"/>
    
    <body name="0" pos="0 0 0">
      <camera name="track" mode="trackcom" pos="0 -3 0.3" xyaxes="1 0 0 0 0 1"/>
      <geom pos="0 0 0" size="0.25" type="sphere"/>
      <joint armature="0" damping="0" limited="false" margin="0.01" name="root" pos="0 0 0" type="free"/>
      <body name="1" pos="0 0 0">
        <joint axis="-0.707107 0.707107 0" name="1_joint" pos="0 0 0" range="-30 30" type="hinge"/>
        <geom fromto="0 0 0 0.4 0.4 0" size="0.08" type="capsule"/>
      </body>
      <body name="2" pos="0 0 0">
        <joint axis="-0.707107 -0.707107 0" name="2_joint" pos="0 0 0" range="-30 30" type="hinge"/>
        <geom fromto="0 0 0 -0.4 0.4 0" size="0.08" type="capsule"/>
      </body>
      <body name="3" pos="0 0 0">
        <joint axis="0.707107 -0.707107 0" name="3_joint" pos="0 0 0" range="-30 30" type="hinge"/>
        <geom fromto="0 0 0 -0.4 -0.4 0" size="0.08" type="capsule"/>
      </body>
      <body name="4" pos="0 0 0">
        <joint axis="0.707107 0.707107 0" name="4_joint" pos="0 0 0" range="-30 30" type="hinge"/>
        <geom fromto="0 0 0 0.4 -0.4 0" size="0.08" type="capsule"/>
      </body>
    </body>
  </worldbody>
  <actuator>
    <motor ctrllimited="true" ctrlrange="-1.0 1.0" joint="1_joint" gear="150" name="1_joint"/>
    <motor ctrllimited="true" ctrlrange="-1.0 1.0" joint="2_joint" gear="150" name="2_joint"/>
    <motor ctrllimited="true" ctrlrange="-1.0 1.0" joint="3_joint" gear="150" name="3_joint"/>
    <motor ctrllimited="true" ctrlrange="-1.0 1.0" joint="4_joint" gear="150" name="4_joint"/>
  </actuator>
  <asset>
    <texture type="skybox" builtin="gradient" rgb1=".4 .5 .6" rgb2="0 0 0" width="100" height="100"/>
    <texture builtin="flat" height="1278" mark="cross" markrgb="1 1 1" name="texgeom" random="0.01" rgb1="0.8 0.6 0.4" rgb2="0.8 0.6 0.4" type="cube" width="127"/>
    <texture builtin="checker" height="100" name="texplane" rgb1="0 0 0" rgb2="0.8 0.8 0.8" type="2d" width="100"/>
    <material name="MatPlane" reflectance="0.5" shininess="1" specular="1" texrepeat="60 60" texture="texplane"/>
    <material name="geom" texture="texgeom" texuniform="true"/>
    <hfield name="stair" size = "51 100 40 0.125" file="/tmp/mujoco_terrains/stair_terrain.png"/>
    <texture name="grid_new" type="2d" builtin="checker" rgb1=".1 .3 .2" rgb2=".2 .4 .3" width="1000" height="1000" mark="none" markrgb=".8 .6 .4"/>
    <material name="grid_new" texture="grid_new" texrepeat="0.0 0.2" texuniform="true" reflectance=".2"/>
  </asset>
</mujoco>
